Workbook

Sheet 01 Dashboard
B1: REVII · WRIST-WEARABLE BENCHMARK — EXECUTIVE DASHBOARD
B2: Research as of 27 Oct 2026 · Wonlex wrist wearables vs Revii's customer research · every figure below recalculates from the input sheets
B4: =IF(COUNTIF('10 Scoring & Weights'!$S$87:$S$99,"Eligible")=0,"No wearable is confirmed eligible yet — none has supplier-verified data access. "&IF('11 Ranking & Shortlist'!C41="","No model is conditionally eligible either — see the pending-verification list.","Provisional leader: "&'11 Ranking & Shortlist'!C41&" ("&TEXT('11 Ranking & Shortlist'!D41,"0.0")&"/100)"&IF('11 Ranking & Shortlist'!C42="","",", then "&'11 Ranking & Shortlist'!C42&IF('11 Ranking & Shortlist'!C43="",""," and "&'11 Ranking & Shortlist'!C43)&", all within "&TEXT('11 Ranking & Shortlist'!D41-MIN('11 Ranking & Shortlist'!D41:D43),"0.0")&" points — a tie on current evidence")&". Treat these as the models to verify, not a purchase decision."),COUNTIF('10 Scoring & Weights'!$S$87:$S$99,"Eligible")&" model(s) eligible. Confirmed leader: "&'11 Ranking & Shortlist'!C24&".") -> No wearable is confirmed eligible yet — none has supplier-verified data access. Provisional leader: HW19 (55.8/100), then CT34 and VB10, all within 2.6 points — a tie on current evidence. Treat these as the models to verify, not a purchase decision.
B6: Manufacturers authorised | C6: Models catalogued | D6: Wrist models scored | E6: Eligible (all gates passed) | F6: Conditionally eligible | G6: Pending verification | H6: Open P1 supplier questions | I6: Fleet used for TCO
B7: =SUMPRODUCT(1/COUNTIF('02 Model Master List'!$B$6:$B$53,'02 Model Master List'!$B$6:$B$53)) -> 5 | C7: =COUNTA('02 Model Master List'!$C$6:$C$53) -> 48 | D7: =COUNTA('03 Feature Comparison'!$C$6:$C$18) -> 13 | E7: =COUNTIF('10 Scoring & Weights'!$S$87:$S$99,"Eligible") -> 0 | F7: =COUNTIF('10 Scoring & Weights'!$S$87:$S$99,"Conditionally eligible") -> 3 | G7: =COUNTIF('10 Scoring & Weights'!$S$87:$S$99,"Pending verification") -> 10 | H7: =COUNTIFS('15 Data Gaps & Questions'!$F$5:$F$60,"P1",'15 Data Gaps & Questions'!$H$5:$H$60,"<>Verified") -> 13 | I7: ='08 TCO Model'!$C$22 -> 1000
B9: Provisional ranking — conditionally eligible models (shortlist for supplier verification; none is eligible yet)
B10: # | C10: Model | D10: Overall | E10: Market fit (confirmed – potential) | F10: Integration | G10: Commercial | H10: TCO 36m / device (EUR) | I10: Integration status | J10: Eligibility | K10: Confidence | L10: Strongest need
B11: 1 | C11: ='11 Ranking & Shortlist'!C41 -> HW19 | D11: ='11 Ranking & Shortlist'!D41 -> 55.767454 | E11: =IF(C11="","",ROUND(INDEX('10 Scoring & Weights'!$J$87:$J$99,MATCH(C11,'10 Scoring & Weights'!$C$87:$C$99,0)),0)&" – "&ROUND(INDEX('10 Scoring & Weights'!$K$87:$K$99,MATCH(C11,'10 Scoring & Weights'!$C$87:$C$99,0)),0)) -> 57 – 94 | F11: ='11 Ranking & Shortlist'!F41 -> 53.75 | G11: ='11 Ranking & Shortlist'!G41 -> 30.562055 | H11: ='11 Ranking & Shortlist'!H41 -> 189.7286 | I11: ='11 Ranking & Shortlist'!K41 -> Conditional | J11: ='11 Ranking & Shortlist'!I41 -> Conditionally eligible | K11: ='11 Ranking & Shortlist'!J41 -> Medium | L11: =IF(C11="","",INDEX('06 Needs-Feature Map'!$Q$113:$Q$125,MATCH(C11,'06 Needs-Feature Map'!$C$113:$C$125,0))) -> N1
B12: 2 | C12: ='11 Ranking & Shortlist'!C42 -> CT34 | D12: ='11 Ranking & Shortlist'!D42 -> 55.034149 | E12: =IF(C12="","",ROUND(INDEX('10 Scoring & Weights'!$J$87:$J$99,MATCH(C12,'10 Scoring & Weights'!$C$87:$C$99,0)),0)&" – "&ROUND(INDEX('10 Scoring & Weights'!$K$87:$K$99,MATCH(C12,'10 Scoring & Weights'!$C$87:$C$99,0)),0)) -> 50 – 96 | F12: ='11 Ranking & Shortlist'!F42 -> 50 | G12: ='11 Ranking & Shortlist'!G42 -> 43.538109 | H12: ='11 Ranking & Shortlist'!H42 -> 140.1386 | I12: ='11 Ranking & Shortlist'!K42 -> Conditional | J12: ='11 Ranking & Shortlist'!I42 -> Conditionally eligible | K12: ='11 Ranking & Shortlist'!J42 -> Low | L12: =IF(C12="","",INDEX('06 Needs-Feature Map'!$Q$113:$Q$125,MATCH(C12,'06 Needs-Feature Map'!$C$113:$C$125,0))) -> N1
B13: 3 | C13: ='11 Ranking & Shortlist'!C43 -> VB10 | D13: ='11 Ranking & Shortlist'!D43 -> 53.207128 | E13: =IF(C13="","",ROUND(INDEX('10 Scoring & Weights'!$J$87:$J$99,MATCH(C13,'10 Scoring & Weights'!$C$87:$C$99,0)),0)&" – "&ROUND(INDEX('10 Scoring & Weights'!$K$87:$K$99,MATCH(C13,'10 Scoring & Weights'!$C$87:$C$99,0)),0)) -> 53 – 91 | F13: ='11 Ranking & Shortlist'!F43 -> 40 | G13: ='11 Ranking & Shortlist'!G43 -> 61.117119 | H13: ='11 Ranking & Shortlist'!H43 -> 93.23 | I13: ='11 Ranking & Shortlist'!K43 -> Conditional | J13: ='11 Ranking & Shortlist'!I43 -> Conditionally eligible | K13: ='11 Ranking & Shortlist'!J43 -> Medium | L13: =IF(C13="","",INDEX('06 Needs-Feature Map'!$Q$113:$Q$125,MATCH(C13,'06 Needs-Feature Map'!$C$113:$C$125,0))) -> N3
B14: 4 | C14: ='11 Ranking & Shortlist'!C44 | D14: ='11 Ranking & Shortlist'!D44 | E14: =IF(C14="","",ROUND(INDEX('10 Scoring & Weights'!$J$87:$J$99,MATCH(C14,'10 Scoring & Weights'!$C$87:$C$99,0)),0)&" – "&ROUND(INDEX('10 Scoring & Weights'!$K$87:$K$99,MATCH(C14,'10 Scoring & Weights'!$C$87:$C$99,0)),0)) | F14: ='11 Ranking & Shortlist'!F44 | G14: ='11 Ranking & Shortlist'!G44 | H14: ='11 Ranking & Shortlist'!H44 | I14: ='11 Ranking & Shortlist'!K44 | J14: ='11 Ranking & Shortlist'!I44 | K14: ='11 Ranking & Shortlist'!J44 | L14: =IF(C14="","",INDEX('06 Needs-Feature Map'!$Q$113:$Q$125,MATCH(C14,'06 Needs-Feature Map'!$C$113:$C$125,0)))
B15: 5 | C15: ='11 Ranking & Shortlist'!C45 | D15: ='11 Ranking & Shortlist'!D45 | E15: =IF(C15="","",ROUND(INDEX('10 Scoring & Weights'!$J$87:$J$99,MATCH(C15,'10 Scoring & Weights'!$C$87:$C$99,0)),0)&" – "&ROUND(INDEX('10 Scoring & Weights'!$K$87:$K$99,MATCH(C15,'10 Scoring & Weights'!$C$87:$C$99,0)),0)) | F15: ='11 Ranking & Shortlist'!F45 | G15: ='11 Ranking & Shortlist'!G45 | H15: ='11 Ranking & Shortlist'!H45 | I15: ='11 Ranking & Shortlist'!K45 | J15: ='11 Ranking & Shortlist'!I45 | K15: ='11 Ranking & Shortlist'!J45 | L15: =IF(C15="","",INDEX('06 Needs-Feature Map'!$Q$113:$Q$125,MATCH(C15,'06 Needs-Feature Map'!$C$113:$C$125,0)))
B17: Strong candidates still PENDING verification (no model-specific integration evidence yet) — top 3
B18: # | C18: Model | D18: Overall | E18: Market fit | F18: Integration | G18: Commercial | H18: TCO 36m / device (EUR) | I18: Integration status | J18: Eligibility | K18: Confidence
B19: 1 | C19: ='11 Ranking & Shortlist'!C58 -> HW20 | D19: ='11 Ranking & Shortlist'!D58 -> 55.888039 | E19: ='11 Ranking & Shortlist'!E58 -> 76.832089 | F19: ='11 Ranking & Shortlist'!F58 -> 32.5 | G19: ='11 Ranking & Shortlist'!G58 -> 34.562055 | H19: ='11 Ranking & Shortlist'!H58 -> 189.7286 | I19: ='11 Ranking & Shortlist'!K58 -> Not verified | J19: ='11 Ranking & Shortlist'!I58 -> Pending verification | K19: ='11 Ranking & Shortlist'!J58 -> Low
B20: 2 | C20: ='11 Ranking & Shortlist'!C59 -> MF90 | D20: ='11 Ranking & Shortlist'!D59 -> 50.896513 | E20: ='11 Ranking & Shortlist'!E59 -> 70.370989 | F20: ='11 Ranking & Shortlist'!F59 -> 22.5 | G20: ='11 Ranking & Shortlist'!G59 -> 56.5 | H20: ='11 Ranking & Shortlist'!H59 -> 66.69935 | I20: ='11 Ranking & Shortlist'!K59 -> Not verified | J20: ='11 Ranking & Shortlist'!I59 -> Pending verification | K20: ='11 Ranking & Shortlist'!J59 -> Medium
B21: 3 | C21: ='11 Ranking & Shortlist'!C60 -> CT31 | D21: ='11 Ranking & Shortlist'!D60 -> 50.075791 | E21: ='11 Ranking & Shortlist'!E60 -> 58.34465 | F21: ='11 Ranking & Shortlist'!F60 -> 32.5 | G21: ='11 Ranking & Shortlist'!G60 -> 55.201092 | H21: ='11 Ranking & Shortlist'!H60 -> 137.1632 | I21: ='11 Ranking & Shortlist'!K60 -> Not verified | J21: ='11 Ranking & Shortlist'!I60 -> Pending verification | K21: ='11 Ranking & Shortlist'!J60 -> Low
B22: ="Confirmed ranking: "&'11 Ranking & Shortlist'!B22 -> Confirmed ranking: No model currently passes all three mandatory gates — no confirmed ranking can be issued. See the provisional ranking.
B24: Best model by use case — within the ranking pool (live, from 13 and 11)
B25: Use case | C25: Top model | D25: Score | E25: Eligibility | F25: Runner-up
B26: ='13 Sensitivity & Scenarios'!C75 -> Market-research baseline | C26: ='13 Sensitivity & Scenarios'!D75 -> HW19 | D26: ='13 Sensitivity & Scenarios'!E75 -> 55.767454 | E26: ='13 Sensitivity & Scenarios'!F75 -> Conditionally eligible | F26: ='13 Sensitivity & Scenarios'!G75 -> CT34
B27: ='13 Sensitivity & Scenarios'!C76 -> Safety-first | C27: ='13 Sensitivity & Scenarios'!D76 -> HW19 | D27: ='13 Sensitivity & Scenarios'!E76 -> 58.412243 | E27: ='13 Sensitivity & Scenarios'!F76 -> Conditionally eligible | F27: ='13 Sensitivity & Scenarios'!G76 -> CT34
B28: ='13 Sensitivity & Scenarios'!C77 -> Wellbeing monitoring | C28: ='13 Sensitivity & Scenarios'!D77 -> VB10 | D28: ='13 Sensitivity & Scenarios'!E77 -> 56.053326 | E28: ='13 Sensitivity & Scenarios'!F77 -> Conditionally eligible | F28: ='13 Sensitivity & Scenarios'!G77 -> HW19
B29: ='13 Sensitivity & Scenarios'!C78 -> Ease-of-use | C29: ='13 Sensitivity & Scenarios'!D78 -> CT34 | D29: ='13 Sensitivity & Scenarios'!E78 -> 55.949167 | E29: ='13 Sensitivity & Scenarios'!F78 -> Conditionally eligible | F29: ='13 Sensitivity & Scenarios'!G78 -> HW19
B30: ='13 Sensitivity & Scenarios'!C79 -> Cost-efficiency | C30: ='13 Sensitivity & Scenarios'!D79 -> VB10 | D30: ='13 Sensitivity & Scenarios'!E79 -> 54.761902 | E30: ='13 Sensitivity & Scenarios'!F79 -> Conditionally eligible | F30: ='13 Sensitivity & Scenarios'!G79 -> CT34
B31: ='13 Sensitivity & Scenarios'!C80 -> Segment: independent / stable seniors | C31: ='13 Sensitivity & Scenarios'!D80 -> VB10 | D31: ='13 Sensitivity & Scenarios'!E80 -> 55.566467 | E31: ='13 Sensitivity & Scenarios'!F80 -> Conditionally eligible | F31: ='13 Sensitivity & Scenarios'!G80 -> CT34
B32: ='13 Sensitivity & Scenarios'!C81 -> Segment: vulnerable / higher dependency | C32: ='13 Sensitivity & Scenarios'!D81 -> HW19 | D32: ='13 Sensitivity & Scenarios'!E81 -> 56.707616 | E32: ='13 Sensitivity & Scenarios'!F81 -> Conditionally eligible | F32: ='13 Sensitivity & Scenarios'!G81 -> CT34
B33: Best cost-to-value (score per EUR 100 of 36-month TCO) | C33: =IFERROR(INDEX('11 Ranking & Shortlist'!$C$7:$C$19,MATCH(MAX('11 Ranking & Shortlist'!$T$7:$T$19),'11 Ranking & Shortlist'!$T$7:$T$19,0)),"") -> VB10 | D33: =MAX('11 Ranking & Shortlist'!$T$7:$T$19) -> 57.070823
B35: Critical uncertainties — open P1 supplier questions (15)
B36: ='15 Data Gaps & Questions'!B5 -> CT29 | C36: ='15 Data Gaps & Questions'!C5 -> Product identity and specification sheet | G36: ='15 Data Gaps & Questions'!D5 -> Supplied URL shows the S10 kids watch; no CT29 spec page exists | L36: ='15 Data Gaps & Questions'!H5 -> Open
B37: ='15 Data Gaps & Questions'!B6 -> CT34 | C37: ='15 Data Gaps & Questions'!C6 -> Health sensors on CT34 | G37: ='15 Data Gaps & Questions'!D6 -> Determines whether CT34 can serve early-decline needs (N2) or safety only | L37: ='15 Data Gaps & Questions'!H6 -> Open
B38: ='15 Data Gaps & Questions'!B7 -> CT34 | C38: ='15 Data Gaps & Questions'!C7 -> TCP protocol document and event list | G38: ='15 Data Gaps & Questions'!D7 -> Mandatory data-access gate | L38: ='15 Data Gaps & Questions'!H7 -> Open
B39: ='15 Data Gaps & Questions'!B8 -> CT34 | C39: ='15 Data Gaps & Questions'!C8 -> Two-way calling hardware; SIM size; EU operator testing | G39: ='15 Data Gaps & Questions'!D8 -> SOS without voice is weaker; SIM logistics | L39: ='15 Data Gaps & Questions'!H8 -> Open
B40: ='15 Data Gaps & Questions'!B9 -> VB10 | C40: ='15 Data Gaps & Questions'!C9 -> SDK support and licence | G40: ='15 Data Gaps & Questions'!D9 -> Mandatory data-access gate for VB10 | L40: ='15 Data Gaps & Questions'!H9 -> Open
B41: ='15 Data Gaps & Questions'!B10 -> VB10 | C41: ='15 Data Gaps & Questions'!C10 -> Fall detection / button | G41: ='15 Data Gaps & Questions'!D10 -> Top research need (N1); currently Unknown | L41: ='15 Data Gaps & Questions'!H10 -> Open
B42: ='15 Data Gaps & Questions'!B11 -> VB10 | C42: ='15 Data Gaps & Questions'!C11 -> Medical claims and estimation features | G42: ='15 Data Gaps & Questions'!D11 -> Regulatory exposure (MDR / AI Act) | L42: ='15 Data Gaps & Questions'!H11 -> Open
B43: ='15 Data Gaps & Questions'!B12 -> HW19 | C43: ='15 Data Gaps & Questions'!C12 -> KSCtracker API and hosting | G43: ='15 Data Gaps & Questions'!D12 -> Integration and GDPR transfer assessment | L43: ='15 Data Gaps & Questions'!H12 -> Open
B45: Charts
H62: Colours: categorical pair validated for colour-vision deficiency. Bars share one axis per chart; the market-fit chart's gap between the two bars is the share of each score that still rests on Unknown evidence.

Sheet 02 Model Master List
A1: MODEL MASTER LIST
A2: Every product considered: user-mandated, historical, discovered alternatives and screened-out items (with reasons). Scope: wrist-worn devices only.
A3: Authorised manufacturers: Wonlex (mandatory list + historical), 2M Engineering, Shelly, Aeotec, OWON (historical workbook). No other manufacturer was introduced. Excluded by scope: smart glasses (incl. Dinowear AI Glasses), rings and every other non-wrist category. No separate manufacturer/model list file was provided; the six images in the historical workbook are captures of Wonlex product pages (S39).
A5: ID | B5: Manufacturer | C5: Model | D5: Product category | E5: Form factor | F5: Official product URL | G5: Original source / input | H5: Classification | I5: Mandatory vs discovered | J5: Market availability | K5: Inclusion / exclusion rationale | L5: Integration status | M5: Eligibility | N5: Research completeness | O5: Notes
A6: M01 | B6: Wonlex | C6: VB10 | D6: Screenless BLE health band | E6: Wrist — band | F6: https://www.iwonlex.net/products/vb10-medical-grade-screenless-health-band-with-ecg-and-hrv-monitoring/ | G6: Brief — mandatory model | H6: User-mandated | I6: Mandatory | J6: Listed on manufacturer site (May 2026 spec) | K6: Mandatory. Richest physiological sensing (ECG 500 Hz, HRV, SpO2, sleep stages) with a public-but-licensed SDK pointer. | L6: ='04 API & Integration'!K6 -> Conditional | M6: ='10 Scoring & Weights'!S87 -> Conditionally eligible | N6: ='10 Scoring & Weights'!L87 -> 0.72222222
A7: M02 | B7: Wonlex | C7: CT29 | D7: 4G health bracelet with fall detection | E7: Wrist — band | F7: https://www.iwonlex.net/products/wonlex-4g-cheap-gps-wifi-calling-cat1-kids-smart-watch-s10/ | G7: Brief — mandatory model | H7: User-mandated | I7: Mandatory | J7: Name listed on manufacturer category page; no spec page found | K7: Mandatory. Supplied URL resolves to the S10 KIDS watch; CT29 specifications could not be established and S10 specs are not transferred. | L7: ='04 API & Integration'!K7 -> Not verified | M7: ='10 Scoring & Weights'!S88 -> Pending verification | N7: ='10 Scoring & Weights'!L88 -> 0.13513514
A8: M03 | B8: Wonlex | C8: CT34 | D8: 4G GPS screenless SOS band for seniors | E8: Wrist — band | F8: https://www.iwonlex.net/products/wonlex-ct34-4g-gps-screenless-sos-smart-band-for-seniors/ | G8: Brief — mandatory model | H8: User-mandated | I8: Mandatory | J8: Listed on manufacturer site; Alibaba storefront | K8: Mandatory. Simplest safety device: screenless, fall detection, SOS call, 4G, TCP integration stated on the model page. | L8: ='04 API & Integration'!K8 -> Conditional | M8: ='10 Scoring & Weights'!S89 -> Conditionally eligible | N8: ='10 Scoring & Weights'!L89 -> 0.51351351
A9: M04 | B9: Wonlex | C9: MF90 | D9: BLE screenless ECG & health band | E9: Wrist — band | F9: https://www.iwonlex.net/products/mf90-bluetooth-screenless-ecg---health-monitoring-band/ | G9: Historical workbook | H9: Historical comparison model | I9: Historical | J9: Listed on manufacturer site | K9: In historical benchmark; screenless ECG band, 7-15 day battery. | L9: ='04 API & Integration'!K9 -> Not verified | M9: ='10 Scoring & Weights'!S90 -> Pending verification | N9: ='10 Scoring & Weights'!L90 -> 0.61111111
A10: M05 | B10: Wonlex | C10: MF91 | D10: BLE screenless fitness/health bracelet | E10: Wrist — band | F10: https://www.iwonlex.net/products/mf91-screenless-health-fitness-bracelet-for-gym-and-sports-monitoring-band/ | G10: Historical workbook | H10: Historical comparison model | I10: Historical | J10: Listed on manufacturer site ('offline sale only, not for USA') | K10: In historical benchmark (only model with a cost); 28 g, lightest device. | L10: ='04 API & Integration'!K10 -> Not verified | M10: ='10 Scoring & Weights'!S91 -> Pending verification | N10: ='10 Scoring & Weights'!L91 -> 0.55555556
A11: M06 | B11: Wonlex | C11: MF40 | D11: BLE AMOLED watch with air-pump BP and ECG | E11: Wrist — watch | F11: https://www.iwonlex.net/top-5-smart-health-watches-for-seniors-aging-in-place/ | G11: Historical workbook | H11: Historical comparison model | I11: Historical | J11: Described on manufacturer articles; product page not captured | K11: In historical benchmark; only BLE device with cuff-type (air-pump) blood pressure. | L11: ='04 API & Integration'!K11 -> Not verified | M11: ='10 Scoring & Weights'!S92 -> Pending verification | N11: ='10 Scoring & Weights'!L92 -> 0.52777778
A12: M07 | B12: Wonlex | C12: HW20 | D12: 4G senior watch with air-pump BP | E12: Wrist — watch | F12: https://www.iwonlex.net/products/wonlex-hw20-4g-gps-senior-health-smartwatch-with-air-pump-blood-pressure-monitor/ | G12: Historical workbook | H12: Historical comparison model | I12: Historical | J12: Listed on manufacturer site | K12: In historical benchmark (cost 77); combines 4G safety with cuff-type BP. | L12: ='04 API & Integration'!K12 -> Not verified | M12: ='10 Scoring & Weights'!S93 -> Pending verification | N12: ='10 Scoring & Weights'!L93 -> 0.51351351
A13: M08 | B13: Wonlex | C13: MF91Pro | D13: BLE screenless medical-marketed ECG band | E13: Wrist — band | F13: https://www.iwonlex.net/products/mf91pro-medical-grade-screenless-health-band-with-ecg-and-hrv-monitoring/ | G13: Discovered — Wonlex catalogue | H13: Additional shortlisted alternative | I13: Discovered | J13: Listed on manufacturer site | K13: Same documented platform as VB10 (nRF54L15, TI4950, 265 mAh); included to test whether VB10 has an interchangeable second source. | L13: ='04 API & Integration'!K13 -> Not verified | M13: ='10 Scoring & Weights'!S94 -> Pending verification | N13: ='10 Scoring & Weights'!L94 -> 0.33333333
A14: M09 | B14: Wonlex | C14: HW20Pro | D14: 4G + BLE watch with air-pump BP | E14: Wrist — watch | F14: https://www.iwonlex.net/products/wonlex-4g-ble-medical-air-pump-smartwatch-hw20pro--precision-bp---senior-health-monitoring/ | G14: Discovered — Wonlex catalogue | H14: Additional shortlisted alternative | I14: Discovered | J14: Listed on manufacturer site; Alibaba listing | K14: Successor to historical HW20 with documented fall detection and power-saving BLE co-processor. | L14: ='04 API & Integration'!K14 -> Not verified | M14: ='10 Scoring & Weights'!S95 -> Pending verification | N14: ='10 Scoring & Weights'!L95 -> 0.40540541
A15: M10 | B15: Wonlex | C15: HW19 | D15: 4G AMOLED senior health watch | E15: Wrist — watch | F15: https://www.iwonlex.net/products/hw19-4g-senior-health-smartwatch-with-sos-and-gps/ | G15: Discovered — Wonlex catalogue | H15: Additional shortlisted alternative | I15: Discovered | J15: Listed on manufacturer site | K15: Only model documenting multi-sensor (barometric) fall detection; KSCtracker platform named on the model page. | L15: ='04 API & Integration'!K15 -> Conditional | M15: ='10 Scoring & Weights'!S96 -> Conditionally eligible | N15: ='10 Scoring & Weights'!L96 -> 0.64864865
A16: M11 | B16: Wonlex | C16: CT20S | D16: 4G senior watch with fall detection | E16: Wrist — watch | F16: https://www.iwonlex.net/products/wonlex-ct20s-4g-smart-watch-for-elderly-with-large-screen-and-fall-detection/ | G16: Discovered — Wonlex catalogue | H16: Additional shortlisted alternative | I16: Discovered | J16: Listed on manufacturer site | K16: Large-screen 4G watch with automatic fall-triggered SOS and IP67; screen-based alternative to CT34. | L16: ='04 API & Integration'!K16 -> Not verified | M16: ='10 Scoring & Weights'!S97 -> Pending verification | N16: ='10 Scoring & Weights'!L97 -> 0.43243243
A17: M12 | B17: Wonlex | C17: CT30 (band) | D17: 4G GPS senior band with HR/BP | E17: Wrist — band | F17: https://www.iwonlex.net/products/wonlex-4g-cat1-hr-br-monitoring-gps-kids-watch-s8-with-wifi-sos/ | G17: Discovered — Wonlex catalogue | H17: Additional shortlisted alternative | I17: Discovered | J17: Listed on manufacturer site | K17: 4G band adding HR/BP and activity to SOS + GPS; candidate middle ground between CT34 and VB10. | L17: ='04 API & Integration'!K17 -> Not verified | M17: ='10 Scoring & Weights'!S98 -> Pending verification | N17: ='10 Scoring & Weights'!L98 -> 0.32432432
A18: M13 | B18: Wonlex | C18: CT31 | D18: 4G screenless two-button senior band | E18: Wrist — band | F18: https://www.iwonlex.net/products/4g-ct31-screenless-senior-band-with-dual-big-button-and-big-battery/ | G18: Discovered — Wonlex catalogue | H18: Additional shortlisted alternative | I18: Discovered | J18: Listed on manufacturer site; Alibaba MOQ 2 | K18: Screenless, largest battery (950 mAh), dedicated health-check and SOS buttons; positioned for telecare integrators. | L18: ='04 API & Integration'!K18 -> Not verified | M18: ='10 Scoring & Weights'!S99 -> Pending verification | N18: ='10 Scoring & Weights'!L99 -> 0.43243243
A19: X01 | B19: Wonlex | C19: S10 | D19: 4G kids smartwatch | E19: Wrist | G19: URL supplied for CT29 | H19: Screened out | I19: Discovered | K19: Children's product with touch screen; it is what the supplied CT29 URL shows. Recorded to prevent its specifications being attributed to CT29. | L19: — | M19: Screened out | N19: —
A20: X02 | B20: Wonlex | C20: CT10T | D20: 4G senior smartwatch | E20: Wrist | G20: Discovered — Wonlex catalogue | H20: Screened out | I20: Discovered | K20: SOS/HR/BP watch without documented fall detection; functionally dominated by CT20S (same chipset class, adds fall detection). | L20: — | M20: Screened out | N20: —
A21: X03 | B21: Wonlex | C21: KT17S | D21: 4G SOS senior smartwatch | E21: Wrist | G21: Discovered — Wonlex catalogue | H21: Screened out | I21: Discovered | K21: Marginal variant of the CT20S/HW19 class; fall detection only in a third-party search summary. | L21: — | M21: Screened out | N21: —
A22: X04 | B22: Wonlex | C22: KT43 | D22: 4G Android senior smartwatch | E22: Wrist | G22: Discovered — Wonlex catalogue | H22: Screened out | I22: Discovered | K22: Full Android OS raises power draw and interface complexity — contrary to the research priority on ease of use. | L22: — | M22: Screened out | N22: —
A23: X05 | B23: Wonlex | C23: MF19 / MF30 | D23: BLE AMOLED ECG / BP watches | E23: Wrist | G23: Discovered — Wonlex catalogue | H23: Screened out | I23: Discovered | K23: Near-duplicates of MF40 (BLE, AMOLED, ECG/air-pump BP); MF40 retained as the representative. | L23: — | M23: Screened out | N23: —
A24: X06 | B24: Wonlex | C24: CT30 Pro | D24: 4G senior smartwatch | E24: Wrist | G24: Discovered — marketplace | H24: Screened out | I24: Discovered | K24: Watch-format variant of CT30; CT30 band retained. | L24: — | M24: Screened out | N24: —
A25: X07 | B25: Wonlex | C25: Marsfit Apex ring | D25: Smart ring | E25: Ring | G25: Discovered — Wonlex catalogue | H25: Screened out | I25: Discovered | K25: Not wrist-worn (ring) — outside product scope. | L25: — | M25: Screened out | N25: —
A26: X08 | B26: Wonlex | C26: KT34 / KT10 / CT10 kids watches | D26: Kids smartwatches | E26: Wrist | G26: Discovered — Wonlex catalogue | H26: Screened out | I26: Discovered | K26: Children's products. | L26: — | M26: Screened out | N26: —
A27: H01 | B27: 2M Engineering | C27: Health Patch Platform | D27: Chest/body patch | E27: Non-wrist | G27: Historical workbook | H27: Screened out | I27: Historical | K27: Not wrist-worn (adhesive patch). | L27: — | M27: Screened out | N27: —
A28: H02 | B28: 2M Engineering | C28: P-CARDIO HP201 | D28: 1-lead ECG patch | E28: Non-wrist | G28: Historical workbook | H28: Screened out | I28: Historical | K28: Not wrist-worn (patch). | L28: — | M28: Screened out | N28: —
A29: H03 | B29: 2M Engineering | C29: T-Sense Smart Shirt | D29: Smart textile | E29: Non-wrist | G29: Historical workbook | H29: Screened out | I29: Historical | K29: Not wrist-worn (garment). | L29: — | M29: Screened out | N29: —
A30: H04 | B30: 2M Engineering | C30: Activ8 Platform | D30: Activity monitor | E30: Non-wrist | G30: Historical workbook | H30: Screened out | I30: Historical | K30: Prescribed wear location is trouser pocket / thigh (S36). | L30: — | M30: Screened out | N30: —
... A53: I22 | B53: OWON | C53: WPS311-Z | D53: Ambient IoT sensor / switch / button | E53: Non-wrist (home) | G53: Historical workbook | H53: Screened out | I53: Historical | K53: Not wrist-worn — outside this benchmark; retained for the IoT Monitor roadmap. | L53: — | M53: Screened out | N53: —

Sheet 03 Feature Comparison
A1: DETAILED FEATURE COMPARISON — HARDWARE CAPABILITY
A2: Rows = shortlisted wrist wearables. Status = what the HARDWARE offers per captured evidence (Revii's data access is separate: 04). Hover any status cell for grade, source and note.
A3: Legend: | B3: Yes | C3: Conditional | D3: Unknown | E3: No | F3: N/A | G3: Unknown ≠ No: Unknown means no captured evidence either way. Blue status cells are editable — update them as suppliers answer and every score recalculates.
F4: Physiological | G4: Physiological | H4: Physiological | I4: Physiological | J4: Physiological | K4: Physiological | L4: Physiological | M4: Physiological | N4: Physiological | O4: Safety | P4: Safety | Q4: Safety | R4: Safety | S4: Safety | T4: Connectivity | U4: Connectivity | V4: Usability | W4: Wellbeing | X4: Risk flag | Y4: Privacy | Z4: Connectivity | AA4: Usability | AC4: Specifications (numbers are numeric; blank = not captured)
A5: ID | B5: Manufacturer | C5: Model | D5: Form | E5: Link | F5: F01 Heart rate | G5: F02 Heart-rate variability (HRV) | H5: F03 ECG | I5: F04 SpO2 | J5: F05 Blood pressure | K5: F06 Body / skin temperature | L5: F07 Sleep monitoring | M5: F08 Steps & activity | N5: F09 Stress indicator | O5: F10 Automatic fall detection | P5: F11 SOS button | Q5: F12 Two-way voice calling | R5: F13 GNSS positioning | S5: F14 Geofencing | T5: F15 Standalone 4G/LTE | U5: F16 Works without a smartphone | V5: F17 Screenless / minimal interface | W5: F18 Medication reminder | X5: F19 Non-invasive glucose / lipid estimation | Y5: F20 No camera | Z5: F21 Offline on-device data storage | AA5: F22 Water resistance IP67 or better | AC5: Chipset / sensor platform | AD5: Connectivity | AE5: LTE bands | AF5: Battery (mAh) | AG5: Battery life — typical use, lower bound (days) | AH5: Battery evidence | AI5: Battery note | AJ5: Weight (g) | AK5: Dimensions | AL5: Display | AM5: Water rating | AN5: Charging | AO5: SIM | AP5: App / platform | AQ5: Sampling mode
A6: M01 | B6: Wonlex | C6: VB10 | D6: Band | E6: BLE | F6: Yes | G6: Yes | H6: Yes | I6: Yes | J6: Unknown | K6: Yes | L6: Yes | M6: Yes | N6: Yes | O6: Unknown | P6: Unknown | Q6: Unknown | R6: No | S6: No | T6: No | U6: No | V6: Yes | W6: Unknown | X6: Yes | Y6: Yes | Z6: Unknown | AA6: Yes | AC6: Nordic nRF54L15 + TI4950 AFE | AD6: BLE 6.0 | AE6: — | AF6: 265 | AG6: 10 | AH6: X | AI6: Spec table 'active up to 10 d'; intro says '10 d standby' | AK6: Not captured | AL6: Screenless | AM6: IP68 | AN6: Magnetic pin dock | AO6: — | AP6: Gband Companion App; SDK pointer github.com/HBandSDK | AQ6: Real-time optical; ECG 500 Hz / PPG 50 Hz
A7: M02 | B7: Wonlex | C7: CT29 | D7: Band | E7: 4G | F7: Unknown | G7: Unknown | H7: Unknown | I7: Unknown | J7: Unknown | K7: Unknown | L7: Unknown | M7: Unknown | N7: Unknown | O7: Yes | P7: Unknown | Q7: Unknown | R7: Unknown | S7: Unknown | T7: Yes | U7: Conditional | V7: Unknown | W7: Unknown | X7: Unknown | Y7: Unknown | Z7: Unknown | AA7: Unknown | AD7: 4G (per name) | AE7: Unknown | AK7: Unknown | AL7: Unknown | AM7: Unknown | AN7: Unknown | AO7: Unknown | AP7: Unknown | AQ7: Unknown
A8: M03 | B8: Wonlex | C8: CT34 | D8: Band | E8: 4G | F8: Unknown | G8: Unknown | H8: Unknown | I8: Unknown | J8: Unknown | K8: Unknown | L8: Unknown | M8: Unknown | N8: Unknown | O8: Yes | P8: Yes | Q8: Conditional | R8: Yes | S8: Unknown | T8: Yes | U8: Yes | V8: Yes | W8: Unknown | X8: Unknown | Y8: Yes | Z8: Unknown | AA8: Yes | AC8: ASR3603S (RTOS) | AD8: 4G Cat1 + GSM | AE8: B1/B2/B3/B5/B7/B8/B20 | AF8: 530 | AG8: 3 | AH8: B | AI8: 3-5 days continuous use claimed | AK8: Not captured | AL8: Screenless | AM8: IP67 | AN8: Not captured | AO8: Not captured | AP8: TCP protocol to care platform | AQ8: Not documented
A9: M04 | B9: Wonlex | C9: MF90 | D9: Band | E9: BLE | F9: Yes | G9: Yes | H9: Yes | I9: Yes | J9: Conditional | K9: Yes | L9: Yes | M9: Yes | N9: Yes | O9: Unknown | P9: Unknown | Q9: Unknown | R9: No | S9: No | T9: No | U9: No | V9: Yes | W9: Yes | X9: Yes | Y9: Yes | Z9: Unknown | AA9: Yes | AC9: PPG GH3228T | AD9: BLE 5.3 | AE9: — | AF9: 180 | AG9: 7 | AH9: B | AI9: 7-15 days typical; 30+ days standby | AK9: 42.3 x 27.4 x 8.0 mm | AL9: Screenless | AM9: IP68 | AN9: Magnetic | AO9: — | AP9: Companion app; remote family view | AQ9: 24 h HR; ECG 500 Hz
A10: M05 | B10: Wonlex | C10: MF91 | D10: Band | E10: BLE | F10: Yes | G10: Yes | H10: Unknown | I10: Yes | J10: Conditional | K10: Yes | L10: Yes | M10: Yes | N10: Yes | O10: Unknown | P10: Unknown | Q10: Unknown | R10: No | S10: No | T10: No | U10: No | V10: Yes | W10: Yes | X10: Yes | Y10: Yes | Z10: Unknown | AA10: Yes | AC10: JL7013A | AD10: BLE 5.3 + NFC | AE10: — | AF10: 125 | AG10: 7 | AH10: B | AI10: 7-15 days typical; 30+ days standby | AJ10: 28 | AK10: 39 x 29 x 10 mm | AL10: Screenless | AM10: IP68 | AN10: Magnetic | AO10: — | AP10: Companion app | AQ10: 24 h HR
A11: M06 | B11: Wonlex | C11: MF40 | D11: Watch | E11: BLE | F11: Yes | G11: Unknown | H11: Yes | I11: Yes | J11: Yes | K11: Unknown | L11: Yes | M11: Yes | N11: Yes | O11: Unknown | P11: Unknown | Q11: Unknown | R11: No | S11: No | T11: No | U11: No | V11: No | W11: Unknown | X11: Unknown | Y11: Yes | Z11: Unknown | AA11: No | AC11: TI4950 ECG; Murata air pump | AD11: BLE 5.3 | AE11: — | AI11: Not found (MF30 sibling: 300 mAh — not transferred) | AK11: Not captured | AL11: AMOLED touchscreen (size conflicting) | AM11: IP66 | AN11: Not captured | AO11: — | AP11: Companion app | AQ11: 24/7 HR & SpO2
A12: M07 | B12: Wonlex | C12: HW20 | D12: Watch | E12: 4G | F12: Yes | G12: Unknown | H12: Unknown | I12: Yes | J12: Yes | K12: Unknown | L12: Yes | M12: Yes | N12: Unknown | O12: Yes | P12: Yes | Q12: Yes | R12: Yes | S12: Unknown | T12: Yes | U12: Yes | V12: No | W12: Unknown | X12: Yes | Y12: Yes | Z12: Unknown | AA12: Unknown | AC12: Not captured | AD12: 4G LTE + BT 5.0 | AE12: B1/B3/B7/B8/B20/B28A | AI12: Not stated on manufacturer page | AK12: Not captured | AL12: 1.78" 368x448 touchscreen | AM12: Not captured | AN12: Magnetic | AO12: Not captured | AP12: Not captured | AQ12: Continuous HR & SpO2
A13: M08 | B13: Wonlex | C13: MF91Pro | D13: Band | E13: BLE | F13: Yes | G13: Yes | H13: Yes | I13: Unknown | J13: Unknown | K13: Unknown | L13: Unknown | M13: Unknown | N13: Unknown | O13: Unknown | P13: Unknown | Q13: Unknown | R13: No | S13: No | T13: No | U13: No | V13: Yes | W13: Unknown | X13: Yes | Y13: Yes | Z13: Unknown | AA13: Unknown | AC13: Nordic nRF54L15 + TI4950 AFE | AD13: BLE 6.0 | AE13: — | AF13: 265 | AI13: Only '10 days standby' stated | AK13: Not captured | AL13: Screenless | AM13: Not captured | AN13: Not captured | AO13: — | AP13: Not captured | AQ13: ECG 500 Hz
A14: M09 | B14: Wonlex | C14: HW20Pro | D14: Watch | E14: 4G | F14: Unknown | G14: Unknown | H14: Unknown | I14: Unknown | J14: Yes | K14: Unknown | L14: Unknown | M14: Unknown | N14: Unknown | O14: Yes | P14: Yes | Q14: Yes | R14: Yes | S14: Unknown | T14: Yes | U14: Yes | V14: No | W14: Unknown | X14: Yes | Y14: Yes | Z14: Unknown | AA14: Yes | AC14: Not captured; BLE co-processor | AD14: 4G + BLE | AE14: Per HW20 family (unconfirmed) | AF14: 540 | AG14: 4 | AH14: C | AI14: Up to 4 days (marketplace) | AK14: Not captured | AL14: 1.96" AMOLED (marketplace) | AM14: IP67 (marketplace) | AN14: Not captured | AO14: Not captured | AP14: Not captured | AQ14: Not documented
A15: M10 | B15: Wonlex | C15: HW19 | D15: Watch | E15: 4G | F15: Yes | G15: Yes | H15: Unknown | I15: Yes | J15: Conditional | K15: Unknown | L15: Yes | M15: Unknown | N15: Unknown | O15: Yes | P15: Yes | Q15: Yes | R15: Yes | S15: Unknown | T15: Yes | U15: Yes | V15: No | W15: Unknown | X15: Yes | Y15: Yes | Z15: Unknown | AA15: Unknown | AC15: Not captured | AD15: 4G LTE + BT 5.3 | AE15: Not captured | AF15: 800 | AI15: Runtime not stated | AK15: Not captured | AL15: 1.96" AMOLED | AM15: Not captured | AN15: Magnetic | AO15: Nano SIM | AP15: KSCtracker platform | AQ15: Not documented
A16: M11 | B16: Wonlex | C16: CT20S | D16: Watch | E16: 4G | F16: Yes | G16: Unknown | H16: Unknown | I16: Unknown | J16: Unknown | K16: Yes | L16: Yes | M16: Unknown | N16: Unknown | O16: Yes | P16: Yes | Q16: Unknown | R16: Yes | S16: Yes | T16: Yes | U16: Yes | V16: No | W16: Unknown | X16: Unknown | Y16: Yes | Z16: Unknown | AA16: Yes | AC16: Not captured | AD16: 4G | AE16: Not captured | AF16: 680 | AH16: X | AI16: Product page 680 mAh; blog 650 mAh / 4 days standby | AK16: Not captured | AL16: 1.85" IPS 240x280 | AM16: IP67 | AN16: Magnetic | AO16: Not captured | AP16: Not captured | AQ16: Alerts outside preset ranges
A17: M12 | B17: Wonlex | C17: CT30 (band) | D17: Band | E17: 4G | F17: Yes | G17: Unknown | H17: Unknown | I17: Unknown | J17: Conditional | K17: Unknown | L17: Unknown | M17: Yes | N17: Unknown | O17: Unknown | P17: Yes | Q17: Yes | R17: Yes | S17: Unknown | T17: Yes | U17: Yes | V17: Unknown | W17: Unknown | X17: Unknown | Y17: Yes | Z17: Unknown | AA17: Unknown | AC17: ASR3603S | AD17: 4G Cat1 | AE17: Not captured | AF17: 700 | AI17: Runtime not stated | AK17: Not captured | AL17: Not captured | AM17: Not captured | AN17: Magnetic USB | AO17: Nano SIM | AP17: Not captured | AQ17: Not documented
A18: M13 | B18: Wonlex | C18: CT31 | D18: Band | E18: 4G | F18: Yes | G18: Unknown | H18: Unknown | I18: Yes | J18: Conditional | K18: Yes | L18: Unknown | M18: Unknown | N18: Unknown | O18: Unknown | P18: Yes | Q18: Yes | R18: Yes | S18: Unknown | T18: Yes | U18: Yes | V18: Yes | W18: Unknown | X18: Unknown | Y18: Yes | Z18: Unknown | AA18: Yes | AC18: ASR3603C (RTOS) | AD18: 4G FDD-LTE | AE18: Not captured | AF18: 950 | AI18: 'Multi-day' only | AJ18: 40 | AK18: 40.5 x 50 x 14.6 mm | AL18: Screenless, 2 large buttons | AM18: IP67 | AN18: Magnetic | AO18: Micro SIM | AP18: Positioned for telecare integrators | AQ18: One-touch (on-demand) health check
A21: Evidence grade per hardware status cell (A verified · B strong · C indicative · D unverified · X contradicted · blank = no claim). Feeds the evidence-quality confidence indicator.
A22: ID | B22: Manufacturer | C22: Model | F22: F01 | G22: F02 | H22: F03 | I22: F04 | J22: F05 | K22: F06 | L22: F07 | M22: F08 | N22: F09 | O22: F10 | P22: F11 | Q22: F12 | R22: F13 | S22: F14 | T22: F15 | U22: F16 | V22: F17 | W22: F18 | X22: F19 | Y22: F20 | Z22: F21 | AA22: F22
A23: M01 | C23: VB10 | F23: B | G23: B | H23: B | I23: B | K23: B | L23: B | M23: B | N23: B | R23: C | S23: C | T23: B | U23: B | V23: B | X23: B | Y23: C | AA23: B
A24: M02 | C24: CT29 | O24: C | T24: C | U24: C
A25: M03 | C25: CT34 | O25: B | P25: B | Q25: B | R25: B | T25: B | U25: B | V25: B | Y25: C | AA25: B
A26: M04 | C26: MF90 | F26: B | G26: B | H26: B | I26: B | J26: B | K26: B | L26: B | M26: C | N26: B | R26: C | S26: C | T26: B | U26: B | V26: B | W26: B | X26: B | Y26: C | AA26: B
A27: M05 | C27: MF91 | F27: B | G27: B | H27: X | I27: B | J27: B | K27: B | L27: B | M27: B | N27: B | R27: C | S27: C | T27: B | U27: B | V27: B | W27: B | X27: B | Y27: C | AA27: B
A28: M06 | C28: MF40 | F28: B | H28: B | I28: B | J28: B | L28: C | M28: C | N28: B | R28: C | S28: C | T28: B | U28: B | V28: B | Y28: C | AA28: B
A29: M07 | C29: HW20 | F29: B | I29: B | J29: B | L29: B | M29: C | O29: C | P29: B | Q29: B | R29: B | T29: B | U29: B | V29: B | X29: B | Y29: C
A30: M08 | C30: MF91Pro | F30: C | G30: B | H30: B | R30: C | S30: C | T30: B | U30: B | V30: B | X30: B | Y30: C
A31: M09 | C31: HW20Pro | J31: B | O31: B | P31: B | Q31: B | R31: C | T31: B | U31: B | V31: C | X31: C | Y31: C | AA31: C
A32: M10 | C32: HW19 | F32: B | G32: B | I32: B | J32: B | L32: B | O32: B | P32: B | Q32: B | R32: B | T32: B | U32: B | V32: B | X32: B | Y32: C
A33: M11 | C33: CT20S | F33: B | K33: B | L33: C | O33: B | P33: C | R33: B | S33: C | T33: B | U33: B | V33: B | Y33: C | AA33: B
A34: M12 | C34: CT30 (band) | F34: B | J34: B | M34: B | P34: B | Q34: B | R34: B | T34: B | U34: B | Y34: C
A35: M13 | C35: CT31 | F35: B | I35: B | J35: B | K35: B | P35: B | Q35: B | R35: B | T35: B | U35: B | V35: B | Y35: C | AA35: B
A38: Technical-depth criteria (Functional dimension B) — HOW WELL capabilities are implemented, distinct from market fit (WHETHER they exist). Weights live on 10.
A39: ID | B39: Manufacturer | C39: Model | F39: T1 Automatic / continuous physiological sampling | G39: T2 ECG waveform at >=250 Hz documented | H39: T3 Fall-detection method (Y = multi-sensor documented; C = method unspecified) | I39: T4 Multi-mode positioning (GNSS + Wi-Fi/LBS) | J39: T5 Offline storage / store-and-forward | K39: T6 Blood-pressure method (Y = oscillometric cuff; C = estimate) | L39: T7 LTE bands cover PT/ES operators (B3, B7, B20) | N39: Grade T1 | O39: T2 | P39: T3 | Q39: T4 | R39: T5 | S39: T6 | T39: T7
E40: Weight → | F40: ='10 Scoring & Weights'!$D$32 -> 25 | G40: ='10 Scoring & Weights'!$D$33 -> 10 | H40: ='10 Scoring & Weights'!$D$34 -> 25 | I40: ='10 Scoring & Weights'!$D$35 -> 15 | J40: ='10 Scoring & Weights'!$D$36 -> 5 | K40: ='10 Scoring & Weights'!$D$37 -> 10 | L40: ='10 Scoring & Weights'!$D$38 -> 10
A41: M01 | C41: VB10 | F41: Yes | G41: Yes | H41: Unknown | I41: No | J41: Unknown | K41: Unknown | L41: N/A | N41: B | O41: B | Q41: C
A42: M02 | C42: CT29 | F42: Unknown | G42: Unknown | H42: Conditional | I42: Unknown | J42: Unknown | K42: Unknown | L42: Unknown | P42: C
A43: M03 | C43: CT34 | F43: Unknown | G43: Unknown | H43: Conditional | I43: Yes | J43: Unknown | K43: Unknown | L43: Yes | P43: B | Q43: B | T43: B
A44: M04 | C44: MF90 | F44: Yes | G44: Yes | H44: Unknown | I44: No | J44: Unknown | K44: Conditional | L44: N/A | N44: B | O44: B | Q44: C | S44: B
...

Sheet 04 API & Integration
A1: API & INTEGRATION — CAN REVII ACTUALLY GET THE DATA?
A2: Hardware capability is not integration capability. Only 'Verified feasible' can pass the integration gate; nothing is verified until a supplier confirms in writing.
A4: 1. Integration overview (Integration status is an editable input — it drives mandatory gate G1)
A5: ID | B5: Model | C5: Connectivity | D5: API / SDK type | E5: Documentation | F5: Synchronisation | G5: Smartphone dependence | H5: Backend requirements | I5: API restrictions | J5: Licensing | K5: Integration status | L5: Required verification actions
A6: M01 | B6: VB10 | C6: BLE | D6: Phone-side BLE SDK (Veepoo HBandSDK, Android AAR + iOS framework) | E6: Public GitHub repo; VB10 support list not published | F6: Phone-mediated; real-time when in range; periodic history pull (to confirm) | G6: High — needs senior's phone (63-64% of seniors use one) or a home BLE gateway | H6: Revii app running in background on Android/iOS; or gateway | I6: SDK for authorised cooperative customers; device list unknown | J6: Unknown — SDK licence required | K6: Conditional | L6: Obtain written confirmation VB10 is HBandSDK-supported; licence & fees; iOS SDK; field list incl. raw ECG/HRV; background-sync limits
A7: M02 | B7: CT29 | C7: 4G | D7: Unknown — presumably Wonlex 4G TCP protocol | E7: None found | F7: Unknown | G7: None if 4G as named | H7: Unknown | I7: Unknown | J7: Unknown | K7: Not verified | L7: Obtain CT29 datasheet and protocol document; confirm it is not the S10 kids watch
A8: M03 | B8: CT34 | C8: 4G | D8: Device-to-server TCP protocol (Wonlex 4G family); server address configurable; optional KSCtracker cloud | E8: Protocol on request; third-party decoders (flespi) for the protocol family | F8: Event push over 4G (TCP); positioning on schedule | G8: None — standalone 4G | H8: TCP listener/decoder on Revii backend (or flespi), SIM provisioning | I8: Some Wonlex firmware encrypted; one report of paid decryption key | J8: Unknown | K8: Conditional | L8: Request CT34 protocol spec (event codes for fall, SOS, battery, wear), encryption status, server re-pointing method, licence fees
A9: M04 | B9: MF90 | C9: BLE | D9: BLE SDK on request (H Band line) | E9: Not model-specific | F9: Phone-mediated | G9: High | H9: Revii app / gateway | I9: Unknown | J9: Unknown | K9: Not verified | L9: Confirm MF90 SDK support and field list
A10: M05 | B10: MF91 | C10: BLE | D10: BLE SDK on request (H Band line) | E10: Not model-specific | F10: Phone-mediated | G10: High | H10: Revii app / gateway | I10: 'Offline sale only — not for USA' | J10: Unknown | K10: Not verified | L10: Confirm MF91 SDK support; resolve ECG conflict
A11: M06 | B11: MF40 | C11: BLE | D11: BLE SDK on request (H Band line) | E11: Not model-specific | F11: Phone-mediated | G11: High | H11: Revii app / gateway | I11: Unknown | J11: Unknown | K11: Not verified | L11: Confirm MF40 SDK support incl. air-pump BP readings
A12: M07 | B12: HW20 | C12: 4G | D12: Wonlex 4G TCP protocol (company-level) | E12: Company-level only | F12: Event push over 4G | G12: None | H12: TCP decoder | I12: Unknown | J12: Unknown | K12: Not verified | L12: Confirm HW20 protocol, BP data fields
A13: M08 | B13: MF91Pro | C13: BLE | D13: BLE SDK (platform identical to VB10; no SDK pointer captured) | E13: Not model-specific | F13: Phone-mediated | G13: High | H13: Revii app / gateway | I13: Unknown | J13: Unknown | K13: Not verified | L13: Confirm MF91Pro vs VB10 relationship and SDK support
A14: M09 | B14: HW20Pro | C14: 4G | D14: Wonlex 4G TCP protocol (company-level) | E14: Company-level only | F14: Event push over 4G | G14: None | H14: TCP decoder | I14: Unknown | J14: Unknown | K14: Not verified | L14: Confirm HW20Pro protocol, fall/BP events
A15: M10 | B15: HW19 | C15: 4G | D15: KSCtracker platform (hosted on AWS) or device TCP to own server | E15: Platform API not public; protocol on request | F15: Platform push / device TCP | G15: None — standalone 4G | H15: Own TCP server or KSCtracker API | I15: Encryption risk; terms unknown | J15: Unknown — platform fee unknown | K15: Conditional | L15: Request KSCtracker API reference, own-server option, AWS region, DPA, per-device fee
A16: M11 | B16: CT20S | C16: 4G | D16: Wonlex 4G TCP protocol (company-level) | E16: Company-level only | F16: Event push over 4G | G16: None | H16: TCP decoder | I16: Unknown | J16: Unknown | K16: Not verified | L16: Confirm CT20S protocol and fall event
... A18: M13 | B18: CT31 | C18: 4G | D18: Not documented — page positions CT31 for telecare & healthcare integrators | E18: Not found | F18: Unknown | G18: None — standalone 4G | H18: Unknown | I18: Unknown | J18: Unknown | K18: Not verified | L18: Strong lead: request CT31 integration interface, health-check data fields, fall-detection status
A20: 2. Integration criteria (dimension C). Status per model — hover for grade and source. Weights are set on 10.
A22: ID | B22: Model | C22: Conn. | D22: I1 Model-specific integration mechanism documented | E22: I2 Interface documentation obtainable (public or on request) | F22: I3 Safety events (fall / SOS) exposed via integration | G22: I4 Physiological data exposed via integration | H22: I5 Raw data available (not only processed values) | I22: I6 Data path independent of the senior's smartphone | J22: I7 Commercial / licensing terms for Revii's use clear | K22: I8 Revii can host the data (no mandatory vendor cloud) | L22: I9 Near-real-time event delivery | M22: Integration score (0-100)
C23: Weight → | D23: ='10 Scoring & Weights'!$D$43 -> 20 | E23: ='10 Scoring & Weights'!$D$44 -> 10 | F23: ='10 Scoring & Weights'!$D$45 -> 20 | G23: ='10 Scoring & Weights'!$D$46 -> 15 | H23: ='10 Scoring & Weights'!$D$47 -> 5 | I23: ='10 Scoring & Weights'!$D$48 -> 10 | J23: ='10 Scoring & Weights'!$D$49 -> 10 | K23: ='10 Scoring & Weights'!$D$50 -> 5 | L23: ='10 Scoring & Weights'!$D$51 -> 5
A24: M01 | B24: VB10 | C24: BLE | D24: Conditional | E24: Conditional | F24: Unknown | G24: Conditional | H24: Conditional | I24: No | J24: Conditional | K24: Conditional | L24: Conditional | M24: ='10 Scoring & Weights'!F87 -> 40
A25: M02 | B25: CT29 | C25: 4G | D25: Unknown | E25: Unknown | F25: Unknown | G25: Unknown | H25: Unknown | I25: Conditional | J25: Unknown | K25: Unknown | L25: Unknown | M25: ='10 Scoring & Weights'!F88 -> 27.5
A26: M03 | B26: CT34 | C26: 4G | D26: Conditional | E26: Conditional | F26: Conditional | G26: Unknown | H26: Unknown | I26: Yes | J26: Conditional | K26: Conditional | L26: Conditional | M26: ='10 Scoring & Weights'!F89 -> 50
A27: M04 | B27: MF90 | C27: BLE | D27: Unknown | E27: Unknown | F27: Unknown | G27: Unknown | H27: Unknown | I27: No | J27: Unknown | K27: Unknown | L27: Unknown | M27: ='10 Scoring & Weights'!F90 -> 22.5
A28: M05 | B28: MF91 | C28: BLE | D28: Unknown | E28: Unknown | F28: Unknown | G28: Unknown | H28: Unknown | I28: No | J28: Unknown | K28: Unknown | L28: Unknown | M28: ='10 Scoring & Weights'!F91 -> 22.5
A29: M06 | B29: MF40 | C29: BLE | D29: Unknown | E29: Unknown | F29: Unknown | G29: Unknown | H29: Unknown | I29: No | J29: Unknown | K29: Unknown | L29: Unknown | M29: ='10 Scoring & Weights'!F92 -> 22.5
A30: M07 | B30: HW20 | C30: 4G | D30: Unknown | E30: Unknown | F30: Unknown | G30: Unknown | H30: Unknown | I30: Yes | J30: Unknown | K30: Unknown | L30: Unknown | M30: ='10 Scoring & Weights'!F93 -> 32.5
A31: M08 | B31: MF91Pro | C31: BLE | D31: Unknown | E31: Unknown | F31: Unknown | G31: Unknown | H31: Unknown | I31: No | J31: Unknown | K31: Unknown | L31: Unknown | M31: ='10 Scoring & Weights'!F94 -> 22.5
A32: M09 | B32: HW20Pro | C32: 4G | D32: Unknown | E32: Unknown | F32: Unknown | G32: Unknown | H32: Unknown | I32: Yes | J32: Unknown | K32: Unknown | L32: Unknown | M32: ='10 Scoring & Weights'!F95 -> 32.5
A33: M10 | B33: HW19 | C33: 4G | D33: Conditional | E33: Conditional | F33: Conditional | G33: Conditional | H33: Unknown | I33: Yes | J33: Conditional | K33: Conditional | L33: Conditional | M33: ='10 Scoring & Weights'!F96 -> 53.75
A34: M11 | B34: CT20S | C34: 4G | D34: Unknown | E34: Unknown | F34: Unknown | G34: Unknown | H34: Unknown | I34: Yes | J34: Unknown | K34: Unknown | L34: Unknown | M34: ='10 Scoring & Weights'!F97 -> 32.5
A35: M12 | B35: CT30 (band) | C35: 4G | D35: Unknown | E35: Unknown | F35: Unknown | G35: Unknown | H35: Unknown | I35: Yes | J35: Unknown | K35: Unknown | L35: Unknown | M35: ='10 Scoring & Weights'!F98 -> 32.5
A36: M13 | B36: CT31 | C36: 4G | D36: Unknown | E36: Unknown | F36: Unknown | G36: Unknown | H36: Unknown | I36: Yes | J36: Unknown | K36: Unknown | L36: Unknown | M36: ='10 Scoring & Weights'!F99 -> 32.5
A38: 3. Revii-accessible data — can Revii obtain each measurement/event through a documented, authorised interface? (N/A = hardware does not offer it)
A40: ID | B40: Model | C40: Conn. | D40: Fall event | E40: SOS event | F40: Location | G40: Heart rate | H40: HRV | I40: ECG raw waveform | J40: SpO2 | K40: Blood pressure | L40: Sleep | M40: Steps / activity | N40: Temperature | O40: Device status (battery / wear / online) | P40: Accessible (Yes or Conditional)
A41: M01 | B41: VB10 | C41: BLE | D41: Unknown | E41: Unknown | F41: N/A | G41: Conditional | H41: Conditional | I41: Conditional | J41: Conditional | K41: Unknown | L41: Unknown | M41: Unknown | N41: Unknown | O41: Unknown | P41: =COUNTIF(D41:O41,"Yes")+COUNTIF(D41:O41,"Conditional") -> 4
A42: M02 | B42: CT29 | C42: 4G | D42: Unknown | E42: Unknown | F42: Unknown | G42: Unknown | H42: Unknown | I42: Unknown | J42: Unknown | K42: Unknown | L42: Unknown | M42: Unknown | N42: Unknown | O42: Unknown | P42: =COUNTIF(D42:O42,"Yes")+COUNTIF(D42:O42,"Conditional") -> 0
A43: M03 | B43: CT34 | C43: 4G | D43: Conditional | E43: Conditional | F43: Conditional | G43: Unknown | H43: Unknown | I43: Unknown | J43: Unknown | K43: Unknown | L43: Unknown | M43: Unknown | N43: Unknown | O43: Conditional | P43: =COUNTIF(D43:O43,"Yes")+COUNTIF(D43:O43,"Conditional") -> 4
A44: M04 | B44: MF90 | C44: BLE | D44: Unknown | E44: Unknown | F44: N/A | G44: Unknown | H44: Unknown | I44: Unknown | J44: Unknown | K44: Unknown | L44: Unknown | M44: Unknown | N44: Unknown | O44: Unknown | P44: =COUNTIF(D44:O44,"Yes")+COUNTIF(D44:O44,"Conditional") -> 0
A45: M05 | B45: MF91 | C45: BLE | D45: Unknown | E45: Unknown | F45: N/A | G45: Unknown | H45: Unknown | I45: Unknown | J45: Unknown | K45: Unknown | L45: Unknown | M45: Unknown | N45: Unknown | O45: Unknown | P45: =COUNTIF(D45:O45,"Yes")+COUNTIF(D45:O45,"Conditional") -> 0
A46: M06 | B46: MF40 | C46: BLE | D46: Unknown | E46: Unknown | F46: N/A | G46: Unknown | H46: Unknown | I46: Unknown | J46: Unknown | K46: Unknown | L46: Unknown | M46: Unknown | N46: Unknown | O46: Unknown | P46: =COUNTIF(D46:O46,"Yes")+COUNTIF(D46:O46,"Conditional") -> 0
...

Sheet 05 Market Research
A1: MARKET RESEARCH CONSOLIDATION
A2: All market-research inputs analysed together. Blue cells (need mapping, interview coding) are editable and flow into 06 Needs-Feature Map.
B4: 1. Research files analysed
B5: ID | C5: File | D5: Research type | E5: Respondent population | F5: Sample / participants | G5: Questions / themes | H5: Key findings | I5: Limitations | J5: Source
B6: R1 | C6: quantitative_reearch.pptx | D6: Quantitative | E6: Informal caregivers of 70+ (buyers) and seniors (users), PT/ES/EN, online Qualtrics | F6: 952 started; 615 qualified caregivers; 546 at value questions (497 caregivers, 49-50 seniors) | G6: Demand, concerns, technology acceptance, feature priorities, WTP, channels | H6: Fall detection, early decline and doctor sharing top features; ease of use and privacy top decision drivers; wearables 86%/70% accepted; cameras rejected by seniors | I6: Online, LinkedIn-heavy, higher-educated, urban, PT-dominant; senior sub-sample ~50; Spain ~76 directional | J6: S40
B7: R2 | C7: Revii_Research_Report.docx | D7: Quantitative (report on R1 survey) | E7: Same survey as R1 | F7: 938 initiated; 543 completed (494 caregivers, 49 seniors) | G7: Narrative report of the same survey | H7: Same direction as R1; several magnitudes differ (e.g., fall detection 73% vs 90.5%) | I7: Same respondents as R1 — NOT counted as independent evidence | J7: S41
B8: R3 | C8: Interview_Status_and__analysis.xlsx | D8: Qualitative | E8: Seniors (A), informal caregivers (B), professional caregivers (C), PT (some ES) | F8: 24 structured interview summaries: 5 A, 14 B, 5 C (business plan cites 27) | G8: Daily life, concerns, technology attitudes, privacy, WTP, professional workflow | H8: Core problem is uncertainty; falls when alone dominate; passive, simple, non-intrusive technology preferred; sedentary behaviour and medication rate highly | I8: Convenience sample from team networks; small n; no statistical inference; possible overlap with survey respondents | J8: S42
B9: Not market research: Revii_product_features.xlsx (historical device benchmark, input A) — used on 02/03. Respondent overlap between the survey (team networks via LinkedIn) and interviews (team personal networks) cannot be established: interview evidence is therefore used only as corroboration (30% weight) and never as a prevalence estimate.
B11: 2. Quantitative batteries used for need importance (survey R1 / S40; R2 reports the same respondents and is not counted again)
B12: B1 · Feature importance — Q37-44: % rating 4-5 (very/extremely important) · caregivers n=497 · seniors n≈50
B13: Item | C13: Caregivers % | D13: Seniors % | E13: Mapped need | F13: Blended index (0-1) | G13: Mapping note | H13: Index = (caregiver share × caregiver % + senior share × senior %) ÷ the highest blended value in the same battery. Blending before normalising avoids amplifying the small senior percentages (n≈50: one respondent ≈ 2 points), and normalising within each battery puts rating, concern and top-3 questions on a common 0-1 footing.
B14: Fall detection | C14: 0.905 | D14: 0.62 | E14: N1 | F14: =('06 Needs-Feature Map'!$C$6*C14+'06 Needs-Feature Map'!$C$7*D14)/SUMPRODUCT(MAX('06 Needs-Feature Map'!$C$6*$C$14:$C$21+'06 Needs-Feature Map'!$C$7*$D$14:$D$21)) -> 1
B15: Early decline detection | C15: 0.771 | D15: 0.48 | E15: N3 | F15: =('06 Needs-Feature Map'!$C$6*C15+'06 Needs-Feature Map'!$C$7*D15)/SUMPRODUCT(MAX('06 Needs-Feature Map'!$C$6*$C$14:$C$21+'06 Needs-Feature Map'!$C$7*$D$14:$D$21)) -> 0.8342892
B16: Doctor data sharing | C16: 0.73 | D16: 0.48 | E16: N6 | F16: =('06 Needs-Feature Map'!$C$6*C16+'06 Needs-Feature Map'!$C$7*D16)/SUMPRODUCT(MAX('06 Needs-Feature Map'!$C$6*$C$14:$C$21+'06 Needs-Feature Map'!$C$7*$D$14:$D$21)) -> 0.79926785
B17: Cognitive monitoring | C17: 0.694 | D17: 0.408 | E17: N3 | F17: =('06 Needs-Feature Map'!$C$6*C17+'06 Needs-Feature Map'!$C$7*D17)/SUMPRODUCT(MAX('06 Needs-Feature Map'!$C$6*$C$14:$C$21+'06 Needs-Feature Map'!$C$7*$D$14:$D$21)) -> 0.74215985
B18: Biometric monitoring | C18: 0.62 | D18: 0.26 | E18: N3 | F18: =('06 Needs-Feature Map'!$C$6*C18+'06 Needs-Feature Map'!$C$7*D18)/SUMPRODUCT(MAX('06 Needs-Feature Map'!$C$6*$C$14:$C$21+'06 Needs-Feature Map'!$C$7*$D$14:$D$21)) -> 0.6247712
B19: Daily check-in calls | C19: 0.612 | D19: 0.4 | E19: — | F19: =('06 Needs-Feature Map'!$C$6*C19+'06 Needs-Feature Map'!$C$7*D19)/SUMPRODUCT(MAX('06 Needs-Feature Map'!$C$6*$C$14:$C$21+'06 Needs-Feature Map'!$C$7*$D$14:$D$21)) -> 0.66918853 | G19: Service-level (Revii Voice Care), not a wearable capability
B20: Daily routine app | C20: 0.565 | D20: 0.26 | E20: — | F20: =('06 Needs-Feature Map'!$C$6*C20+'06 Needs-Feature Map'!$C$7*D20)/SUMPRODUCT(MAX('06 Needs-Feature Map'!$C$6*$C$14:$C$21+'06 Needs-Feature Map'!$C$7*$D$14:$D$21)) -> 0.57779134 | G20: App feature, not a device capability
B21: Home environment monitoring | C21: 0.29 | D21: 0.245 | E21: — | F21: =('06 Needs-Feature Map'!$C$6*C21+'06 Needs-Feature Map'!$C$7*D21)/SUMPRODUCT(MAX('06 Needs-Feature Map'!$C$6*$C$14:$C$21+'06 Needs-Feature Map'!$C$7*$D$14:$D$21)) -> 0.33740085 | G21: Ambient IoT, not wrist-worn
B24: B2 · Concerns — Q18-27: % rating 4-5 (high concern) · caregivers n=497 · seniors n≈56
B25: Item | C25: Caregivers % | D25: Seniors % | E25: Mapped need | F25: Blended index (0-1) | G25: Mapping note
B26: Falls / accidents | C26: 0.548 | D26: 0.071 | E26: N1 | F26: =('06 Needs-Feature Map'!$C$6*C26+'06 Needs-Feature Map'!$C$7*D26)/SUMPRODUCT(MAX('06 Needs-Feature Map'!$C$6*$C$26:$C$35+'06 Needs-Feature Map'!$C$7*$D$26:$D$35)) -> 1
B27: Difficulty calling for help | C27: 0.445 | D27: 0.089 | E27: N2 | F27: =('06 Needs-Feature Map'!$C$6*C27+'06 Needs-Feature Map'!$C$7*D27)/SUMPRODUCT(MAX('06 Needs-Feature Map'!$C$6*$C$26:$C$35+'06 Needs-Feature Map'!$C$7*$D$26:$D$35)) -> 0.83526797
B28: Undetected health problems | C28: 0.362 | D28: 0.071 | E28: N3 | F28: =('06 Needs-Feature Map'!$C$6*C28+'06 Needs-Feature Map'!$C$7*D28)/SUMPRODUCT(MAX('06 Needs-Feature Map'!$C$6*$C$26:$C$35+'06 Needs-Feature Map'!$C$7*$D$26:$D$35)) -> 0.67843912
B29: Cognitive decline | C29: 0.419 | D29: 0.071 | E29: N3 | F29: =('06 Needs-Feature Map'!$C$6*C29+'06 Needs-Feature Map'!$C$7*D29)/SUMPRODUCT(MAX('06 Needs-Feature Map'!$C$6*$C$26:$C$35+'06 Needs-Feature Map'!$C$7*$D$26:$D$35)) -> 0.77698197
B30: Physical decline | C30: 0.493 | D30: 0.071 | E30: N3 | F30: =('06 Needs-Feature Map'!$C$6*C30+'06 Needs-Feature Map'!$C$7*D30)/SUMPRODUCT(MAX('06 Needs-Feature Map'!$C$6*$C$26:$C$35+'06 Needs-Feature Map'!$C$7*$D$26:$D$35)) -> 0.90491479
B31: Medication errors | C31: 0.212 | D31: 0 | E31: N8 | F31: =('06 Needs-Feature Map'!$C$6*C31+'06 Needs-Feature Map'!$C$7*D31)/SUMPRODUCT(MAX('06 Needs-Feature Map'!$C$6*$C$26:$C$35+'06 Needs-Feature Map'!$C$7*$D$26:$D$35)) -> 0.36651025
B32: Forgotten appointments | C32: 0.12 | D32: 0 | E32: — | F32: =('06 Needs-Feature Map'!$C$6*C32+'06 Needs-Feature Map'!$C$7*D32)/SUMPRODUCT(MAX('06 Needs-Feature Map'!$C$6*$C$26:$C$35+'06 Needs-Feature Map'!$C$7*$D$26:$D$35)) -> 0.20745863 | G32: Not addressable by the wearable
B33: Safety at home | C33: 0.302 | D33: 0.036 | E33: — | F33: =('06 Needs-Feature Map'!$C$6*C33+'06 Needs-Feature Map'!$C$7*D33)/SUMPRODUCT(MAX('06 Needs-Feature Map'!$C$6*$C$26:$C$35+'06 Needs-Feature Map'!$C$7*$D$26:$D$35)) -> 0.54877748 | G33: Ambient/home hazards — IoT scope
B34: Inactivity | C34: 0.364 | D34: 0.125 | E34: N7 | F34: =('06 Needs-Feature Map'!$C$6*C34+'06 Needs-Feature Map'!$C$7*D34)/SUMPRODUCT(MAX('06 Needs-Feature Map'!$C$6*$C$26:$C$35+'06 Needs-Feature Map'!$C$7*$D$26:$D$35)) -> 0.72190664
B35: Poor diet | C35: 0.228 | D35: 0 | E35: — | F35: =('06 Needs-Feature Map'!$C$6*C35+'06 Needs-Feature Map'!$C$7*D35)/SUMPRODUCT(MAX('06 Needs-Feature Map'!$C$6*$C$26:$C$35+'06 Needs-Feature Map'!$C$7*$D$26:$D$35)) -> 0.3941714 | G35: Not addressable by the wearable
B38: B3 · Decision drivers — Q36: % selecting in top 3 · caregivers n=497 · seniors n≈50
B39: Item | C39: Caregivers % | D39: Seniors % | E39: Mapped need | F39: Blended index (0-1) | G39: Mapping note
B40: That is easy to use | C40: 0.694 | D40: 0.76 | E40: N4 | F40: =('06 Needs-Feature Map'!$C$6*C40+'06 Needs-Feature Map'!$C$7*D40)/SUMPRODUCT(MAX('06 Needs-Feature Map'!$C$6*$C$40:$C$44+'06 Needs-Feature Map'!$C$7*$D$40:$D$44)) -> 1
B41: That respects privacy | C41: 0.551 | D41: 0.42 | E41: N5 | F41: =('06 Needs-Feature Map'!$C$6*C41+'06 Needs-Feature Map'!$C$7*D41)/SUMPRODUCT(MAX('06 Needs-Feature Map'!$C$6*$C$40:$C$44+'06 Needs-Feature Map'!$C$7*$D$40:$D$44)) -> 0.71686747
B42: Peace of mind to the family | C42: 0.491 | D42: 0.22 | E42: — | F42: =('06 Needs-Feature Map'!$C$6*C42+'06 Needs-Feature Map'!$C$7*D42)/SUMPRODUCT(MAX('06 Needs-Feature Map'!$C$6*$C$40:$C$44+'06 Needs-Feature Map'!$C$7*$D$40:$D$44)) -> 0.5739703 | G42: Outcome of all needs — mapping it would double-count
B43: That it is not expensive | C43: 0.437 | D43: 0.3 | E43: — | F43: =('06 Needs-Feature Map'!$C$6*C43+'06 Needs-Feature Map'!$C$7*D43)/SUMPRODUCT(MAX('06 Needs-Feature Map'!$C$6*$C$40:$C$44+'06 Needs-Feature Map'!$C$7*$D$40:$D$44)) -> 0.55463715 | G43: Handled in the Commercial dimension, not market fit
B44: That gives me more security | C44: 0.404 | D44: 0.28 | E44: — | F44: =('06 Needs-Feature Map'!$C$6*C44+'06 Needs-Feature Map'!$C$7*D44)/SUMPRODUCT(MAX('06 Needs-Feature Map'!$C$6*$C$40:$C$44+'06 Needs-Feature Map'!$C$7*$D$40:$D$44)) -> 0.51386943 | G44: Ambiguous (personal safety vs data security) — not mapped
B47: 3. Other quantitative findings (context — not used as weights)
B48: Question | C48: Finding | D48: Result | E48: Implication for wearable selection | F48: Source
...

Sheet 06 Needs-Feature Map
A1: NEEDS-TO-FEATURE MAPPING
A2: Research finding → customer need → device feature → evaluation criterion → device performance. All weights editable; every step is a formula.
B4: 1. Research-weighting parameters (editable assumptions)
B5: Parameter | C5: Value | D5: Basis
B6: Caregiver (buyer) share in the quantitative blend | C6: 0.7 | D6: Caregivers are the economic buyer (interest 59% vs 38%; WTP; concern 2-3x). Assumption — editable.
B7: Senior (user) share | C7: =1-C6 -> 0.3 | D7: Seniors are the wearer; small n (~50)
B8: Quantitative share of need importance | C8: 0.7 | D8: Survey n=497 vs 24 interviews; qualitative must not dominate by volume. Assumption — editable.
